<?xml version="1.0"?>
<robot name="WPV4_LMS111">

  <!-- material -->
  <material name = "black">
    <color rgba = "0.01 0.01 0.01 1"/>
  </material>
  <material name = "white">
    <color rgba = "0.8 0.8 0.8 1"/>
  </material>
  <material name = "grey">
    <color rgba = "0.2 0.2 0.2 1"/>
  </material>
  <material name = "blue">
    <color rgba = "0.2 0.2 0.9 1"/>
  </material>


<link name="base_footprint">
    <visual>
      <origin xyz="0 0 0" rpy="0 0 0" />
      <geometry>
        <box size="0.05 0.05 0.001" />
      </geometry>
      <material name="TransparentGreen" />
    </visual>
    <collision>
      <origin xyz="0 0 .1" rpy="0 0 0" />
      <geometry>
        <box size="0.76 0.5 .2"/>
      </geometry>
    </collision>
    <inertial>
    <mass value="10"/>
    <inertia ixx="0.4" ixy="0.0" ixz="0.0" iyy="0.4" iyz="0.0" izz="0.2"/>
    </inertial>
</link>

<joint name="base_joint" type="fixed">
  <origin xyz="0 0 0.09" rpy="0 0 0" />
  <parent link="base_footprint"/>
  <child link="base_link" />
</joint>

  <!-- base -->
  <link name="base_link">
  <visual>
   <geometry>
    <cylinder length="0.6" radius="0.0"/>
   </geometry>
   <origin rpy = "0 0 0" xyz = "0 0 0"/>
  </visual>
  </link>

  <!-- body -->
  <link name = "body_link">
    <visual>
      <geometry>
        <mesh filename="package://wpv4_bringup/meshes/body.dae" scale="1 1 1"/>
      </geometry>
      <origin rpy = "1.57 0 1.57" xyz = "-0.38 -0.25 0"/>
    </visual>
    <collision>
      <origin xyz="0 0 .15" rpy="0 0 0" />
      <geometry>
        <box size="0.76 0.5 0.095"/>
      </geometry>
    </collision>
    <inertial>
    <mass value="10"/>
    <inertia ixx="0.4" ixy="0.0" ixz="0.0" iyy="0.4" iyz="0.0" izz="0.2"/>
    </inertial>
  </link>
  <joint name = "base_to_body" type = "fixed">
    <parent link = "base_link"/>
    <child link = "body_link"/>
    <origin rpy="0 0 0" xyz="0 0 0"/> <!--pos-->
  </joint>
  <gazebo reference = "body_link">
            <turnGravityOff>false</turnGravityOff>
  </gazebo>

  <!-- wheel -->
  <link name = "lf_wheel">
    <visual>
      <geometry>
        <mesh filename="package://wpv4_bringup/meshes/wheel.dae" scale="1 1 1"/>
      </geometry>
      <origin rpy = "0 0 0" xyz = "-0.13  -0.04 -0.13"/>
      <material name = "black"/>
    </visual>
    <collision>
      <origin xyz="0 0 0" rpy="1.57 0 0" />
      <geometry>
        <cylinder radius="0.13" length="0.08"/>
      </geometry>
    </collision>
    <inertial>
    <mass value="10"/>
    <inertia ixx="0.4" ixy="0.0" ixz="0.0" iyy="0.4" iyz="0.0" izz="0.2"/>
    </inertial>
  </link>
  <joint name = "base_to_lf_wheal" type = "continuous">
    <axis rpy="0 0 0" xyz="0 1 0"/>
    <parent link = "base_link"/>
    <child link = "lf_wheel"/>
    <origin rpy="0 0 0" xyz="0.135 0.26 0.038"/> <!--pos to base-->
  </joint>
   <gazebo reference = "lf_wheel">
            <mu1 value = "1.0"/>
            <mu2 value = "1.0"/>
            <kp value = "10.0"/>
            <kd value = "1.0"/>
            <fdir1 value = "1 0 0"/>
            <turnGravityOff>true</turnGravityOff>
  </gazebo>

<link name = "rf_wheel">
  <visual>
    <geometry>
      <mesh filename="package://wpv4_bringup/meshes/wheel.dae" scale="1 1 1"/>
    </geometry>
    <origin rpy = "0 0 0" xyz = "-0.13  -0.04 -0.13"/>
    <material name = "black"/>
  </visual>
  <collision>
    <origin xyz="0 0 0" rpy="1.57 0 0" />
    <geometry>
      <cylinder radius="0.13" length="0.08"/>
    </geometry>
  </collision>
  <inertial>
  <mass value="10"/>
  <inertia ixx="0.4" ixy="0.0" ixz="0.0" iyy="0.4" iyz="0.0" izz="0.2"/>
  </inertial>
</link>
<joint name = "base_to_rf_wheal" type = "continuous">
  <axis rpy="0 0 0" xyz="0 -1 0"/>
  <parent link = "base_link"/>
  <child link = "rf_wheel"/>
  <origin rpy="0 0 3.14" xyz="0.135 -0.26 0.038"/> <!--pos-->
</joint>
 <gazebo reference = "rf_wheel">
            <mu1 value = "1.0"/>
            <mu2 value = "1.0"/>
            <kp value = "10.0"/>
            <kd value = "1.0"/>
            <fdir1 value = "1 0 0"/>
            <turnGravityOff>false</turnGravityOff>
        </gazebo>

<link name = "lb_wheel">
  <visual>
    <geometry>
      <mesh filename="package://wpv4_bringup/meshes/wheel.dae" scale="1 1 1"/>
    </geometry>
    <origin rpy = "0 0 0" xyz = "-0.13  -0.04 -0.13"/>
    <material name = "black"/>
  </visual>
  <collision>
    <origin xyz="0 0 0" rpy="1.57 0 0" />
    <geometry>
      <cylinder radius="0.13" length="0.08"/>
    </geometry>
  </collision>
  <inertial>
  <mass value="10"/>
  <inertia ixx="0.4" ixy="0.0" ixz="0.0" iyy="0.4" iyz="0.0" izz="0.2"/>
  </inertial>
</link>
<joint name = "base_to_lb_wheal" type = "continuous">
  <axis rpy="0 0 0" xyz="0 1 0"/>
  <parent link = "base_link"/>
  <child link = "lb_wheel"/>
  <origin rpy="0 0 0" xyz="-0.175 0.26 0.038"/> <!--pos to base-->
</joint>
 <gazebo reference = "lb_wheel">
            <mu1 value = "1.0"/>
            <mu2 value = "1.0"/>
            <kp value = "10.0"/>
            <kd value = "1.0"/>
            <fdir1 value = "1 0 0"/>
            <material>Gazebo/Black</material>
            <turnGravityOff>false</turnGravityOff>
        </gazebo>

<link name = "rb_wheel">
  <visual>
    <geometry>
      <mesh filename="package://wpv4_bringup/meshes/wheel.dae" scale="1 1 1"/>
    </geometry>
    <origin rpy = "0 0 0" xyz = "-0.13  -0.04 -0.13"/>
    <material name = "black"/>
  </visual>
  <collision>
    <origin xyz="0 0 0" rpy="1.57 0 0" />
    <geometry>
      <cylinder radius="0.13" length="0.08"/>
    </geometry>
  </collision>
  <inertial>
  <mass value="10"/>
  <inertia ixx="0.4" ixy="0.0" ixz="0.0" iyy="0.4" iyz="0.0" izz="0.2"/>
  </inertial>
</link>
<joint name = "base_to_rb_wheal" type = "continuous">
  <axis rpy="0 0 0" xyz="0 -1 0"/>
  <parent link = "base_link"/>
  <child link = "rb_wheel"/>
  <origin rpy="0 0 3.14" xyz="-0.175 -0.26 0.038"/> <!--pos-->
</joint>
 <gazebo reference = "rb_wheel">
            <mu1 value = "1.0"/>
            <mu2 value = "1.0"/>
            <kp value = "10.0"/>
            <kd value = "1.0"/>
            <fdir1 value = "1 0 0"/>
            <material>Gazebo/Black</material>
            <turnGravityOff>false</turnGravityOff>
        </gazebo>

<!-- Lidar -->
<link name = "laser">
  <visual>
   <geometry>
    <mesh filename="package://lms1xx/meshes/sick-lms1xx.stl" scale="1 1 1"/>
   </geometry>
    <material name = "white"/>
   <origin rpy = "0 0 0" xyz = "0 0 0"/>
  </visual>
  <collision>
    <origin xyz="0 0 0" rpy="0 0 0" />
    <geometry>
      <cylinder radius="0.03" length="0.03"/>
    </geometry>
  </collision>
  <inertial>
  <mass value="10"/>
  <inertia ixx="0.4" ixy="0.0" ixz="0.0" iyy="0.4" iyz="0.0" izz="0.2"/>
  </inertial>
</link>
<joint name="laser_joint" type="fixed">
    <origin rpy="0 0 0" xyz="0.22 0 .27"  /> <!--pos-->
    <parent link="base_link" />
    <child link="laser" />
</joint>

</robot>
