<?xml version="1.0"?>
<robot name="WPV4_MW">

  <!-- material -->
  <material name = "black">
    <color rgba = "0.01 0.01 0.01 1"/>
  </material>
  <material name = "grey">
    <color rgba = "0.2 0.2 0.2 1"/>
  </material>
  <material name = "blue">
    <color rgba = "0.2 0.2 0.9 1"/>
  </material>


<link name="base_footprint">
    <visual>
      <origin xyz="0 0 0" rpy="0 0 0" />
      <geometry>
        <box size="0.05 0.05 0.001" />
      </geometry>
      <material name="TransparentGreen" />
    </visual>
    <collision>
      <origin xyz="0 0 .1" rpy="0 0 0" />
      <geometry>
        <box size="0.76 0.5 .2"/>
      </geometry>
    </collision>
    <inertial>
    <mass value="10"/>
    <inertia ixx="0.4" ixy="0.0" ixz="0.0" iyy="0.4" iyz="0.0" izz="0.2"/>
    </inertial>
</link>

<joint name="base_joint" type="fixed">
  <origin xyz="0 0 0.06" rpy="0 0 0" />
  <parent link="base_footprint"/>
  <child link="base_link" />
</joint>

  <!-- base -->
  <link name="base_link">
  <visual>
   <geometry>
    <cylinder length="0.6" radius="0.0"/>
   </geometry>
   <origin rpy = "0 0 0" xyz = "0 0 0"/>
  </visual>
  </link>

  <!-- body -->
  <link name = "body_link">
    <visual>
      <geometry>
        <mesh filename="package://wpv4/meshes/body.dae" scale="1 1 1"/>
      </geometry>
      <origin rpy = "1.57 0 1.57" xyz = "-0.38 -0.25 0"/>
    </visual>
    <collision>
      <origin xyz="0 0 .15" rpy="0 0 0" />
      <geometry>
        <box size="0.76 0.5 0.095"/>
      </geometry>
    </collision>
    <inertial>
    <mass value="10"/>
    <inertia ixx="0.4" ixy="0.0" ixz="0.0" iyy="0.4" iyz="0.0" izz="0.2"/>
    </inertial>
  </link>
  <joint name = "base_to_body" type = "fixed">
    <parent link = "base_link"/>
    <child link = "body_link"/>
    <origin rpy="0 0 0" xyz="0 0 0"/> <!--pos-->
  </joint>
  <gazebo reference = "body_link">
            <turnGravityOff>false</turnGravityOff>
  </gazebo>

  <!-- wheel -->
  <link name = "lf_wheel">
    <visual>
      <geometry>
        <mesh filename="package://wpv4/meshes/mecanum_a.dae" scale="1 1 1"/>
      </geometry>
      <origin rpy = "1.57 0 0" xyz = "-0.10  0.07 -0.10"/>
      <material name = "black"/>
    </visual>
    <collision>
      <origin xyz="0 0 0" rpy="1.57 0 0" />
      <geometry>
        <cylinder radius="0.13" length="0.08"/>
      </geometry>
    </collision>
    <inertial>
    <mass value="10"/>
    <inertia ixx="0.4" ixy="0.0" ixz="0.0" iyy="0.4" iyz="0.0" izz="0.2"/>
    </inertial>
  </link>
  <joint name = "base_to_lf_wheal" type = "continuous">
    <axis rpy="0 0 0" xyz="0 1 0"/>
    <parent link = "base_link"/>
    <child link = "lf_wheel"/>
    <origin rpy="0 0 0" xyz="0.135 0.26 0.038"/> <!--pos to base-->
  </joint>
   <gazebo reference = "lf_wheel">
            <mu1 value = "1.0"/>
            <mu2 value = "1.0"/>
            <kp value = "10.0"/>
            <kd value = "1.0"/>
            <fdir1 value = "1 0 0"/>
            <turnGravityOff>true</turnGravityOff>
  </gazebo>

<link name = "rf_wheel">
  <visual>
    <geometry>
      <mesh filename="package://wpv4/meshes/mecanum_b.dae" scale="1 1 1"/>
      </geometry>
      <origin rpy = "1.57 0 0" xyz = "-0.10  0.07 -0.10"/>
  </visual>
  <collision>
    <origin xyz="0 0 0" rpy="1.57 0 0" />
    <geometry>
      <cylinder radius="0.13" length="0.08"/>
    </geometry>
  </collision>
  <inertial>
  <mass value="10"/>
  <inertia ixx="0.4" ixy="0.0" ixz="0.0" iyy="0.4" iyz="0.0" izz="0.2"/>
  </inertial>
</link>
<joint name = "base_to_rf_wheal" type = "continuous">
  <axis rpy="0 0 0" xyz="0 -1 0"/>
  <parent link = "base_link"/>
  <child link = "rf_wheel"/>
  <origin rpy="0 0 3.14" xyz="0.135 -0.26 0.038"/> <!--pos-->
</joint>
 <gazebo reference = "rf_wheel">
            <mu1 value = "1.0"/>
            <mu2 value = "1.0"/>
            <kp value = "10.0"/>
            <kd value = "1.0"/>
            <fdir1 value = "1 0 0"/>
            <turnGravityOff>false</turnGravityOff>
        </gazebo>

<link name = "lb_wheel">
  <visual>
    <geometry>
     <mesh filename="package://wpv4/meshes/mecanum_b.dae" scale="1 1 1"/>
      </geometry>
      <origin rpy = "1.57 0 0" xyz = "-0.10  0.07 -0.10"/>
  </visual>
  <collision>
    <origin xyz="0 0 0" rpy="1.57 0 0" />
    <geometry>
      <cylinder radius="0.13" length="0.08"/>
    </geometry>
  </collision>
  <inertial>
  <mass value="10"/>
  <inertia ixx="0.4" ixy="0.0" ixz="0.0" iyy="0.4" iyz="0.0" izz="0.2"/>
  </inertial>
</link>
<joint name = "base_to_lb_wheal" type = "continuous">
  <axis rpy="0 0 0" xyz="0 1 0"/>
  <parent link = "base_link"/>
  <child link = "lb_wheel"/>
  <origin rpy="0 0 0" xyz="-0.175 0.26 0.038"/> <!--pos to base-->
</joint>
 <gazebo reference = "lb_wheel">
            <mu1 value = "1.0"/>
            <mu2 value = "1.0"/>
            <kp value = "10.0"/>
            <kd value = "1.0"/>
            <fdir1 value = "1 0 0"/>
            <turnGravityOff>false</turnGravityOff>
        </gazebo>

<link name = "rb_wheel">
  <visual>
    <geometry>
      <mesh filename="package://wpv4/meshes/mecanum_a.dae" scale="1 1 1"/>
      </geometry>
      <origin rpy = "1.57 0 0" xyz = "-0.10  0.07 -0.10"/>
    <material name = "black"/>
  </visual>
  <collision>
    <origin xyz="0 0 0" rpy="1.57 0 0" />
    <geometry>
      <cylinder radius="0.13" length="0.08"/>
    </geometry>
  </collision>
  <inertial>
  <mass value="10"/>
  <inertia ixx="0.4" ixy="0.0" ixz="0.0" iyy="0.4" iyz="0.0" izz="0.2"/>
  </inertial>
</link>
<joint name = "base_to_rb_wheal" type = "continuous">
  <axis rpy="0 0 0" xyz="0 -1 0"/>
  <parent link = "base_link"/>
  <child link = "rb_wheel"/>
  <origin rpy="0 0 3.14" xyz="-0.175 -0.26 0.038"/> <!--pos-->
</joint>
 <gazebo reference = "rb_wheel">
            <mu1 value = "1.0"/>
            <mu2 value = "1.0"/>
            <kp value = "10.0"/>
            <kd value = "1.0"/>
            <fdir1 value = "1 0 0"/>
            <turnGravityOff>false</turnGravityOff>
        </gazebo>


        <!-- ****manipulator ****-->
         <link name = "mani_base">
            <visual>
                <geometry>
                    <mesh filename="package://wpm2/meshes/base_mod.dae" scale="1 1 1"/>
                </geometry>
                <origin rpy = "1.57 0 1.57" xyz = "-0.067 -0.06 0"/>
            </visual>
        </link>
         <joint name = "base_mani" type = "fixed">
            <parent link = "base_link"/>
            <child link = "mani_base"/>
            <origin xyz = "0.24 0 .16"/>
        </joint>
        <!-- mani_part_1 -->
        <link name = "mani_part_1">
            <visual>
                <geometry>
                    <mesh filename="package://wpm2/meshes/joint_mod_1.dae" scale="1 1 1"/>
                </geometry>
                <origin rpy = "0 0 0" xyz = "-0.046 -0.0675 0"/>
            </visual>
        </link>
         <joint name = "mani_base_1" type = "revolute">
            <parent link = "mani_base"/>
            <child link = "mani_part_1"/>
            <axis xyz = "0 0 1"/>
            <origin xyz = "0 0 0.127"/>
            <limit effort = "1000.0" lower="-3.14" upper="3.14" velocity="0.5"/>
        </joint>
        <!-- mani_part_2 -->
         <link name = "mani_part_2">
            <visual>
                <geometry>
                    <mesh filename="package://wpm2/meshes/joint_mod_2.dae" scale="1 1 1"/>
                </geometry>
                <origin rpy = "1.57 0 0" xyz = " -0.046 0.0675 -0.033"/>
            </visual>
        </link>
         <joint name = "mani_1_2" type = "revolute">
            <parent link = "mani_part_1"/>
            <child link = "mani_part_2"/>
            <axis xyz = "0 1 0"/>
            <origin xyz = "0 0 0.0795"/>
            <limit effort = "1000.0" lower="-3.14" upper="3.14" velocity="0.5"/>
        </joint>
        <!-- mani_part_3 -->
        <link name = "mani_part_3">
            <visual>
                <geometry>
                    <mesh filename="package://wpm2/meshes/joint_mod_1.dae" scale="1 1 1"/>
                </geometry>
                <origin rpy = "0 0 0" xyz = "-0.046 -0.0675 0"/>
            </visual>
        </link>
         <joint name = "mani_2_3" type = "revolute">
            <parent link = "mani_part_2"/>
            <child link = "mani_part_3"/>
            <axis xyz = "0 0 1"/>
            <origin xyz = "0 0 0.1945"/>
            <limit effort = "1000.0" lower="-3.14" upper="3.14" velocity="0.5"/>
        </joint>
        <!-- mani_part_4 -->
         <link name = "mani_part_4">
            <visual>
                <geometry>
                    <mesh filename="package://wpm2/meshes/joint_mod_2.dae" scale="1 1 1"/>
                </geometry>
                <origin rpy = "1.57 0 0" xyz = "-0.046 0.0675 -0.033"/>
            </visual>
        </link>
         <joint name = "mani_3_4" type = "revolute">
            <parent link = "mani_part_3"/>
            <child link = "mani_part_4"/>
            <axis xyz = "0 1 0"/>
            <origin xyz = "0 0 0.0795"/>
            <limit effort = "1000.0" lower="-3.14" upper="3.14" velocity="0.5"/>
        </joint>
        <!-- mani_part_5 -->
        <link name = "mani_part_5">
            <visual>
               <geometry>
                    <mesh filename="package://wpm2/meshes/joint_mod_1.dae" scale="1 1 1"/>
                </geometry>
                <origin rpy = "0 0 0" xyz = "-0.046 -0.0675 0"/>
            </visual>
        </link>
         <joint name = "mani_4_5" type = "revolute">
            <parent link = "mani_part_4"/>
            <child link = "mani_part_5"/>
            <axis xyz = "0 0 1"/>
            <origin xyz = "0 0 0.1945"/>
            <limit effort = "1000.0" lower="-3.14" upper="3.14" velocity="0.5"/>
        </joint>
         <!-- mani_part_6 palm-->
         <link name = "mani_part_6">
            <visual>
                <geometry>
                    <mesh filename="package://wpm2/meshes/palm.dae" scale="1 1 1"/>
                </geometry>
                <origin rpy = "1.57 0 1.57" xyz = "-0.067 -0.062 -0.033"/>
            </visual>
        </link>
         <joint name = "mani_5_6" type = "revolute">
            <parent link = "mani_part_5"/>
            <child link = "mani_part_6"/>
            <axis xyz = "0 1 0"/>
            <origin xyz = "0 0 0.0795"/>
            <limit effort = "1000.0" lower="-3.14" upper="3.14" velocity="0.5"/>
        </joint>

        <!-- finger -->
         <link name = "mani_left_finger">
            <visual>
                <geometry>
                    <mesh filename="package://wpm2/meshes/finger.dae" scale="1 1 1"/>
                </geometry>
                    <material name = "grey"/>
                <origin rpy = "1.57 0 -1.57" xyz = ".021 0.005 -0.005"/>
            </visual>
        </link>
        <joint name = "mani_palm_finger" type = "revolute">
            <parent link = "mani_part_6"/>
            <child link = "mani_left_finger"/>
            <origin xyz = "0 0.06 0.219"/>
            <axis xyz = "-1 0 0"/>
            <limit effort = "1000.0" lower="0" upper="1.0" velocity="0.5"/>
        </joint>

         <link name = "mani_right_finger">
            <visual>
                <geometry>
                    <mesh filename="package://wpm2/meshes/finger.dae" scale="1 1 1"/>
                </geometry>
                    <material name = "grey"/>
                <origin rpy = "1.57 0 1.57" xyz = "-0.0175 -0.005 -0.005"/>
            </visual>
        </link>
        <joint name = "mani_palm_right_finger" type = "revolute">
            <parent link = "mani_part_6"/>
            <child link = "mani_right_finger"/>
            <origin xyz = "0 -0.06 0.219"/>
            <axis xyz = "1 0 0"/>
            <limit effort = "1000.0" lower="0" upper="1.0" velocity="0.5"/>
            <mimic joint = "mani_palm_finger" multiplier = "1" offset = "0"/>
        </joint>
        <!-- *****************-->

<!-- Lidar -->
<link name = "laser">
  <visual>
   <geometry>
    <cylinder length="0" radius="0"/>
   </geometry>
   <origin rpy = "0 0 0" xyz = "0 0 0"/>
  </visual>
  <collision>
    <origin xyz="0 0 0" rpy="0 0 0" />
    <geometry>
      <cylinder radius="0.03" length="0.03"/>
    </geometry>
  </collision>
  <inertial>
  <mass value="10"/>
  <inertia ixx="0.4" ixy="0.0" ixz="0.0" iyy="0.4" iyz="0.0" izz="0.2"/>
  </inertial>
</link>
<joint name="laser_joint" type="fixed">
    <origin rpy="0 0 0" xyz="0.2 0 0"  /> <!--pos-->
    <parent link="base_link" />
    <child link="laser" />
</joint>

<!-- velodyne -->
<link name = "velo_link">
  <visual>
   <geometry>
    <cylinder length="0.00" radius="0.00"/>
   </geometry>
   <origin rpy = "0 0 0" xyz = "0 0 0"/>
  </visual>
</link>
<joint name="velodyne_joint" type="fixed">
    <origin rpy="0 0 0" xyz="0.2 0 1.7"  /> <!--pos-->
    <parent link="base_link" />
    <child link="velo_link" />
</joint>

<!-- Kinect -->
<!-- Kinect -->
<link name = "kinect2_dock">
  <visual>
   <geometry>
    <!-- <box size=".01 .25 .07"/>-->
    <box size="0 0 0"/>
   </geometry>
   <origin rpy = "0 0 0" xyz = "0 0 0"/>
   <material name = "red"/>
  </visual>
</link>
<joint name="kinect_height" type="prismatic">
    <parent link="base_footprint"/>
    <child link="kinect2_dock"/>
    <limit effort="1000.0" lower="0" upper="1.7" velocity="0.5"/>
    <origin xyz="0.174 0 0" rpy="0 -1.5707963 0"/>
  </joint>

<link name = "kinect2_ir_optical_frame">
  <visual>
   <geometry>
    <!-- <box size=".25 .04 .07"/>-->
    <box size="0 0 0"/>
   </geometry>
   <origin xyz = "0 0 0" rpy = "0 0 0"/>
   <material name = "blue"/>
  </visual>
</link>

<joint name="kinect_pitch" type="revolute">
    <axis xyz="1 0 0"/>
    <limit effort="1000.0" lower="-1.57" upper="1.57" velocity="0.5"/>
    <origin xyz="0 0 0" rpy="3.1415926 0 -1.5707963" /> <!--pos-->
    <parent link="kinect2_dock" />
    <child link="kinect2_ir_optical_frame" />
</joint>
<!-- <joint name="kinect_joint" type="fixed">
    <origin xyz="0.174 0 1.35" rpy="-1.5707963 0 -1.5707963" /> 
    <parent link="base_link" />
    <child link="kinect2_ir_optical_frame" />
</joint>-->

<link name = "kinect2_rgb_optical_frame">
  <visual>
   <geometry>
    <box size="0 0 0"/>
   </geometry>
   <origin rpy = "0 0 0" xyz = "0 0 0"/>
   <material name = "blue"/>
  </visual>
</link>
<joint name="kinect_hd_joint" type="fixed">
    <origin xyz="0 0 0" rpy="0 0 0" /> <!--pos-->
    <parent link="kinect2_ir_optical_frame" />
    <child link="kinect2_rgb_optical_frame" />
</joint>

</robot>
